Workbook

Sheet Оферти
A1: Категория | B1: Услуга | C1: Стопанка V1 (24ч портиер) | D1: Стопанка V2 (8 ч портиер) | E1: Стопанка V3 (без портиер) | F1: Стопанка V3 (финална) | G1: FM Solutions (24ч портиер) | H1: FM Solutions (без портиер) | I1: Общ Дом (24ч портиер) | J1: Общ Дом (без портиер) | K1: Габриела Мениджмънт (24ч портиер) | L1: Габриела Мениджмънт (без портиер) | M1: Премиум Естейт | N1: Бележки
A2: Управление | B2: Домоуправител + касиер, Стопанка ООД | C2: 4.17€/ап + 2.08€/паркомясто + 0.83€/мазе | D2: 4.17€/ап + 2.08€/паркомясто + 0.83€/мазе | E2: 4.17€/ап + 2.08€/паркомясто + 0.83€/мазе | F2: 4.17€/ап + 2.08€/паркомясто + 0.83€/мазе | G2: — | H2: — | I2: — | J2: — | L2: =K2 | N2: Стопанка: 5/2.5/1 € с ДДС → /1.20
A3: Управление | B3: Такса управление жилищна част, Стопанка ООД | C3: =4.17*'Жилищна част'!$E$337 -> 650.52 | D3: =4.17*'Жилищна част'!$E$337 -> 650.52 | E3: =4.17*'Жилищна част'!$E$337 -> 650.52 | F3: =5*'Жилищна част'!$E$337 -> 780 | G3: — | H3: — | I3: — | J3: — | L3: =K3
A4: Управление | B4: Такса управление мазета, Стопанка ООД | C4: =0.83*'Жилищна част'!$E$339 -> 43.16 | D4: =0.83*'Жилищна част'!$E$339 -> 43.16 | E4: =0.83*'Жилищна част'!$E$339 -> 43.16 | F4: =1*'Жилищна част'!$E$339 -> 52 | G4: — | H4: — | I4: — | J4: — | L4: =K4
A5: Управление | B5: Такса управление паркоместа, Стопанка ООД | C5: =2.08*'Жилищна част'!$E$340 -> 158.08 | D5: =2.08*'Жилищна част'!$E$340 -> 158.08 | E5: =2.08*'Жилищна част'!$E$340 -> 158.08 | F5: =2.5 * ('Жилищна част'!$E$340 + 'Жилищна част'!$E$338) -> 232.5 | G5: — | H5: — | I5: — | J5: — | L5: =K5
A6: Управление | B6: Такса управление общо, FM Solutions/Общ Дом | C6: — | D6: — | E6: — | G6: 1100 | H6: =G6 -> 1100 | I6: =10*'Жилищна част'!E337 -> 1560 | J6: =I6 -> 1560 | L6: =K6
A7: Управление | B7: Такса управление общо, Габриела Мениджмънт ЕООД | C7: — | D7: — | E7: — | G7: — | H7: — | I7: — | J7: — | K7: =('Жилищна част'!E337*7+'Жилищна част'!E340*3)/1.2 -> 1100 | L7: =K7 -> 1100 | N7: 7Е на апартамент, 3Е на паркомясто
A8: Контрол на достъп | B8: Портиер / охрана | C8: 3500 | D8: ? | E8: — | G8: 3660 | H8: — | I8: 5400 | J8: — | K8: =7185.80631966458/1.2 -> 5988.1719 | L8: — | N8: Стопанка: портиер 4200/1600 € с ДДС → /1.20
A9: Почистване | B9: Почистване – жилищна част | C9: 2500 | D9: 2500 | E9: 2770 | F9: =3330/1.2 -> 2775 | G9: =2450+250 -> 2700 | H9: =G9 -> 2700 | I9: 1500 | J9: =I9 -> 1500 | K9: =1740/1.2 -> 1450 | L9: =K9 -> 1450 | N9: Стопанка: 1800€ с ДДС → 1500 без ДДС → ×(5/3)=2500, FM Solutions: почистване + изтривалки
A10: Почистване | B10: Почистване – гаражи/паркинг (+ фасада/тротоари FM) | C10: 291.67 | D10: 291.67 | E10: 291.67 | F10: =370/1.2 -> 308.33333 | G10: 600 | H10: 600 | I10: 650 | J10: =I10 -> 650 | K10: =2*960/1.2 -> 1600 | L10: =K10 -> 1600 | N10: Стопанка: 350€ с ДДС → /1.20
A11: Външни площи | B11: Зелени площи | C11: 916.67 | D11: 916.67 | E11: 916.67 | F11: =1140/1.2 -> 950 | G11: 675 | H11: =G11 -> 675 | I11: 400 | J11: =I11 -> 400 | K11: =690/1.2 -> 575 | L11: =K11 -> 575 | N11: FM: 900€/месец март–ноември → 900×9/12=675
A12: Външни площи | B12: Снегопочистване | C12: (включено) | D12: (включено) | E12: (включено) | F12: (включено) | G12: 150 | H12: =G12 -> 150 | I12: (включено) | J12: =I12 -> (включено) | K12: — | L12: =K12 -> — | N12: FM: 600E/месец за 3 месеца -> 1800Е/12=150. Това са около 9-10ч на месец през зимата
A13: Техническа | B13: Техническа поддръжка | C13: 583.33 | D13: 583.33 | E13: 583.33 | F13: =700/1.2 -> 583.33333 | G13: (включено) | H13: =G13 -> (включено) | I13: (включено) | J13: =I13 -> (включено) | K13: (включено) | L13: =K13 -> (включено) | N13: Стопанка: 700€ с ДДС → /1.20
A14: Техническа | B14: Асансьор | C14: 630 | D14: 630 | E14: =783/1.2 -> 652.5 | F14: =783/1.2 -> 652.5 | G14: =E14 -> 652.5 | H14: =G14 -> 652.5 | I14: =H14 -> 652.5 | J14: =I14 -> 652.5 | K14: =J14 -> 652.5 | L14: =K14 -> 652.5 | N14: оферта от Alex EA
A15: Режийни | B15: Ток | C15: 739.73 | D15: 739.73 | E15: 739.73 | F15: 739.73 | G15: =E15 -> 739.73 | H15: =G15 -> 739.73 | I15: =H15 -> 739.73 | J15: =I15 -> 739.73 | K15: =J15 -> 739.73 | L15: =K15 -> 739.73 | N15: усреднено от финансов отчет за 2025
A16: Режийни | B16: Вода | C16: 45.29 | D16: 45.29 | E16: =D16 -> 45.29 | F16: =E16 -> 45.29 | G16: =E16 -> 45.29 | H16: =G16 -> 45.29 | I16: =H16 -> 45.29 | J16: =I16 -> 45.29 | K16: =J16 -> 45.29 | L16: =K16 -> 45.29 | N16: усреднено от финансов отчет за 2025
A17: ОБЩО (фиксирани суми) | C17: =SUM(C3:C16) -> 10058.45 | D17: =SUM(D3:D16) -> 6558.45 | E17: =SUM(E3:E16) -> 6850.95 | F17: =SUM(F3:F16) -> 7118.6867 | G17: =SUM(G3:G16) -> 10322.52 | H17: =SUM(H3:H16) -> 6662.52 | I17: =SUM(I3:I16) -> 10947.52 | J17: =SUM(J3:J16) -> 5547.52 | ... L17: =SUM(L3:L16) -> 6162.52 | M17: =M19+M20 -> 17078.313 | N17: Стопанка общо = редове с фиксирани суми; FM “11100” е по офертата
A19: ОБЩО (апартаменти / ателиета / мазета) | C19: =SUM(C3,C4,C8,C9,C11) -> 7610.35 | D19: =SUM(D3,D4,D8,D9,D11) -> 4110.35 | E19: =SUM(E3,E4,E8,E9,E11) -> 4380.35 | F19: =SUM(F3,F4,F8,F9,F11) -> 4557 | G19: =SUM(G3,G4,G8,G9,G11,G12) -> 7185 | H19: =SUM(H3,H4,H8,H9,H11,H12) -> 3525 | I19: =SUM(I3,I4,I8,I9,I11) -> 7300 | J19: =SUM(J3,J4,J8,J9,J11) -> 1900 | K19: =SUM(K3,K4,K8,K9,K11) -> 8013.1719 | L19: =SUM(L3,L4,L8,L9,L11) -> 2025 | M19: =M23*'Жилищна част'!E335 -> 15593.703
A20: ОБЩО (паркоместа / гаражи) | C20: =SUM(C10,C5) -> 449.75 | D20: =SUM(D10,D5) -> 449.75 | E20: =SUM(E10,E5) -> 449.75 | F20: =SUM(F10,F5) -> 540.83333 | G20: =SUM(G10,G5) -> 600 | H20: =SUM(H10,H5) -> 600 | I20: =SUM(I10,I5) -> 650 | J20: =SUM(J10,J5) -> 650 | ... L20: =SUM(L10,L5) -> 1600 | M20: =M24*'Жилищна част'!E336 -> 1484.61
A21: ОБЩО (споделено жилищна площ и сутерен) | C21: =SUM(C13,C15,C16,C14) -> 1998.35 | D21: =SUM(D13,D15,D16,D14) -> 1998.35 | E21: =SUM(E13,E15,E16,E14) -> 2020.85 | F21: =SUM(F13,F15,F16,F14) -> 2020.8533 | G21: =SUM(G13,G15,G16,G14,G6) -> 2537.52 | H21: =SUM(H13,H15,H16,H14,H6) -> 2537.52 | I21: =SUM(I13,I15,I16,I14,I6) -> 2997.52 | J21: =SUM(J13,J15,J16,J14,J6) -> 2997.52 | K21: =SUM(K13,K15,K16,K14,K7) -> 2537.52 | L21: =SUM(L13,L15,L16,L14,L7) -> 2537.52 | M21: 0
A23: Такса на кв.м. жилищна част | C23: =C19/'Жилищна част'!$E$335+C21/('Жилищна част'!$E$335+'Жилищна част'!$E$336) -> 0.53769839 | D23: =D19/'Жилищна част'!$E$335+D21/('Жилищна част'!$E$335+'Жилищна част'!$E$336) -> 0.33569377 | E23: =E19/'Жилищна част'!$E$335+E21/('Жилищна част'!$E$335+'Жилищна част'!$E$336) -> 0.35238561 | F23: =F19/'Жилищна част'!$E$335+F21/('Жилищна част'!$E$335+'Жилищна част'!$E$336) -> 0.36258123 | G23: =G19/'Жилищна част'!$E$335+G21/('Жилищна част'!$E$335+'Жилищна част'!$E$336) -> 0.53971497 | H23: =H19/'Жилищна част'!$E$335+H21/('Жилищна част'!$E$335+'Жилищна част'!$E$336) -> 0.32847586 | I23: =I19/'Жилищна част'!$E$335+I21/('Жилищна част'!$E$335+'Жилищна част'!$E$336) -> 0.56901733 | J23: =J19/'Жилищна част'!$E$335+J21/('Жилищна част'!$E$335+'Жилищна част'!$E$336) -> 0.25735306 | ... L23: =L19/'Жилищна част'!$E$335+L21/('Жилищна част'!$E$335+'Жилищна част'!$E$336) -> 0.24190245 | M23: =0.9 -> 0.9
A24: Такса на кв.м. паркоместа | C24: =(C20)/'Жилищна част'!$E$336+C21/('Жилищна част'!$E$336+'Жилищна част'!$E$335) -> 0.2499332 | D24: =(D20)/'Жилищна част'!$E$336+D21/('Жилищна част'!$E$336+'Жилищна част'!$E$335) -> 0.2499332 | E24: =(E20)/'Жилищна част'!$E$336+E21/('Жилищна част'!$E$336+'Жилищна част'!$E$335) -> 0.25104181 | F24: =(F20)/'Жилищна част'!$E$336+F21/('Жилищна част'!$E$336+'Жилищна част'!$E$335) -> 0.28171782 | G24: =(G20)/'Жилищна част'!$E$336+G21/('Жилищна част'!$E$336+'Жилищна част'!$E$335) -> 0.32710162 | H24: =(H20)/'Жилищна част'!$E$336+H21/('Жилищна част'!$E$336+'Жилищна част'!$E$335) -> 0.32710162 | I24: =(I20)/'Жилищна част'!$E$336+I21/('Жилищна част'!$E$336+'Жилищна част'!$E$335) -> 0.36660612 | J24: =(J20)/'Жилищна част'!$E$336+J21/('Жилищна част'!$E$336+'Жилищна част'!$E$335) -> 0.36660612 | ... L24: =(L20)/'Жилищна част'!$E$336+L21/('Жилищна част'!$E$336+'Жилищна част'!$E$335) -> 0.66389041 | M24: =0.5 -> 0.5
C25: =C24*'Жилищна част'!$E$336 + C23*'Жилищна част'!$E$335 -> 10058.45 | D25: =D24*'Жилищна част'!$E$336 + D23*'Жилищна част'!$E$335 -> 6558.45 | E25: =E24*'Жилищна част'!$E$336 + E23*'Жилищна част'!$E$335 -> 6850.95 | F25: =F24*'Жилищна част'!$E$336 + F23*'Жилищна част'!$E$335 -> 7118.6867 | G25: =G24*'Жилищна част'!$E$336 + G23*'Жилищна част'!$E$335 -> 10322.52 | H25: =H24*'Жилищна част'!$E$336 + H23*'Жилищна част'!$E$335 -> 6662.52 | I25: =I24*'Жилищна част'!$E$336 + I23*'Жилищна част'!$E$335 -> 10947.52 | J25: =J24*'Жилищна част'!$E$336 + J23*'Жилищна част'!$E$335 -> 5547.52 | ... M25: =M24*'Жилищна част'!$E$336 + M23*'Жилищна част'!$E$335 -> 17078.313
A26: Check | C26: =IF(C17=C25, "OK", "WRONG") -> OK | D26: =IF(D17=D25, "OK", "WRONG") -> OK | E26: =IF(E17=E25, "OK", "WRONG") -> OK | F26: =IF(F17=F25, "OK", "WRONG") -> OK | G26: =IF(G17=G25, "OK", "WRONG") -> OK | H26: =IF(H17=H25, "OK", "WRONG") -> OK | I26: =IF(I17=I25, "OK", "WRONG") -> OK | J26: =IF(J17=J25, "OK", "WRONG") -> OK | ... M26: =IF(M17=M25, "OK", "WRONG") -> OK
A28: Фонд ремонти | B28: Жилищна част | C28: 2138 | D28: 2138 | E28: 2138 | F28: 2138 | G28: 2138 | H28: 2138 | I28: 2138 | J28: 2138 | K28: 2138 | L28: 2138 | M28: 2138
A29: Фонд ремонти | B29: Сутерен | C29: =125*3 -> 375 | D29: =125*3 -> 375 | E29: =125*3 -> 375 | F29: =125*3 -> 375 | G29: =125*3 -> 375 | H29: =125*3 -> 375 | I29: =125*3 -> 375 | J29: =125*3 -> 375 | ... M29: =125*3 -> 375
A31: ФР кв.м. жилищна част | C31: =C28/'Жилищна част'!$E$335 -> 0.12339596 | D31: =D28/'Жилищна част'!$E$335 -> 0.12339596 | E31: =E28/'Жилищна част'!$E$335 -> 0.12339596 | F31: =F28/'Жилищна част'!$E$335 -> 0.12339596 | G31: =G28/'Жилищна част'!$E$335 -> 0.12339596 | H31: =H28/'Жилищна част'!$E$335 -> 0.12339596 | I31: =I28/'Жилищна част'!$E$335 -> 0.12339596 | J31: =J28/'Жилищна част'!$E$335 -> 0.12339596 | ... M31: =M28/'Жилищна част'!$E$335 -> 0.12339596
A32: ФР на кв.м. паркоместа | C32: =C29/'Жилищна част'!$E$336 -> 0.12629579 | D32: =D29/'Жилищна част'!$E$336 -> 0.12629579 | E32: =E29/'Жилищна част'!$E$336 -> 0.12629579 | F32: =F29/'Жилищна част'!$E$336 -> 0.12629579 | G32: =G29/'Жилищна част'!$E$336 -> 0.12629579 | H32: =H29/'Жилищна част'!$E$336 -> 0.12629579 | I32: =I29/'Жилищна част'!$E$336 -> 0.12629579 | J32: =J29/'Жилищна част'!$E$336 -> 0.12629579 | ... M32: =M29/'Жилищна част'!$E$336 -> 0.12629579
A34: Въпроси: | D34: =370 / 72 -> 5.1388889 | E34: 1230 | G34: 1000 | H34: 0.3862 | I34: =G34*H34 -> 386.2
A35: - Има ли допълнителна такса за затворените гаражи или ги смятаме към прилежащите им апартаменти? | D35: 700 | E35: 700
D36: 700 | E36: =3 * 1230 -> 3690 | H36: 3330
A39: Площ: | B39: Обекти | C39: Стопанка | D39: Почистване | E39: Поддръжка | G39: Ток | H39: Вода | I39: Асансьори | J39: Двор / Сняг | K39: Ремонт | L39: Общо | M39: 12 месеца:
A40: 17326.34 | B40: Жилища | C40: 874.5 | D40: 3330 | E40: 595 | G40: 629 | H40: 45 | I40: 756 | J40: 1140 | K40: 2138 | L40: =sum(C40:K40) -> 9507.5 | M40: =K40*12 -> 25656
A41: 1082.75 | B41: АБ | C41: 67.5 | D41: 123.333 | E41: 35 | G41: 37 | K41: 125 | L41: =sum(C41:K41) -> 387.833 | M41: =K41*12 -> 1500
A42: 813.48 | B42: ВГ | C42: 50 | D42: 123.333 | E42: 35 | G42: 37 | K42: 125 | L42: =sum(C42:K42) -> 370.333 | M42: =K42*12 -> 1500
A43: 1072.99 | B43: ДЕ | C43: 72.5 | D43: 123.333 | E43: 35 | G43: 37 | K43: 125 | L43: =sum(C43:K43) -> 392.833 | M43: =K43*12 -> 1500
B44: Общо | C44: =sum(C40:C43) -> 1064.5 | D44: =sum(D40:D43) -> 3699.999 | E44: =sum(E40:E43) -> 700 | G44: =sum(G40:G43) -> 740 | H44: =sum(H40:H43) -> 45 | I44: =sum(I40:I43) -> 756 | J44: =sum(J40:J43) -> 1140 | K44: =sum(K40:K43) -> 2513 | L44: =sum(L40:L43) -> 10658.499
A45: =sum(A41:A43) / sum(A40:A43) -> 0.14629899 | C45: =sum(C41:C43) / sum(C40:C43) -> 0.17848755 | D45: =sum(D41:D43) / sum(D40:D43) -> 0.099999757 | E45: =sum(E41:E43) / sum(E40:E43) -> 0.15 | G45: =sum(G41:G43) / sum(G40:G43) -> 0.15 | K45: =sum(K41:K43) / sum(K40:K43) -> 0.14922404

Sheet Жилищна част
A1: ТАБЛИЦА - ПЛОЩОРАЗДЕЛЯНЕ
A2: НА "МНОГОПРОФИЛНА ЖИЛИЩНА СГРАДА С ПОДЗЕМНИ ГАРАЦИ В УПИ V, КВ. 5, М. "НПЗ ХЛАДИЛНИКА - ВИТОША ", РАЙОН "Лозенец"
A3: 1. СГРАДАТА СЕ СЪСТОИ ОТ 128 АПАРТАМЕНТА, 30 АТЕЛИЕТА, 29 ГАРАЖИ, 29 ЕДИНИЧНИ И 47 ДВОЙНИ ПАРКОМЕСТА;
A4: 2. КОНСТРУКЦИЯ
A5: 3. РАЗГЪНАТА ЗАСТР. КВАДР. НА СГРАДАТА, ВКЛ. СУТЕРЕН
A6: 4. РАЗГЪНАТА ЗАСТР. КВАДР. НА ОБЩИТЕ ЧАСТИ ЖИЛИЩА
A7: 5. РАЗГЪНАТА ЗАСТР. КВАДР НА ОБЩИТЕ ЧАСТИ ПОДЗЕМНИ ГАРАЦИ
A8: 6. ПЛОЩ НА УПИ
A9: ЕТ. | B9: К. | C9: АП. № | D9: ОПИСАНИЕ | E9: F1/M2/ | F9: К И.Ч./%/ | G9: К И.Ч. /М2/ | H9: F1 + К И.Ч.
C10: 1 | D10: 2 | E10: 3 | F10: 7
A11: ПОДОБЕКТ: СГРАДА ВХОД "А" И ВХОД "Б"/ПОДОБЕКТ: I ВХОД - А И ВХОД Б/
A12: СУТЕРЕН | B12: -3.3 | C12: ПМ 1-2 | D12: ПАРКОМЯСТО | E12: 15.12 | F12: 0.03862 | G12: 26.7 | H12: =E12+G12 -> 41.82
C13: ПМ 3-4 | D13: ПАРКОМЯСТО | E13: 15.12 | F13: 0.03862 | G13: 26.7 | H13: =E13+G13 -> 41.82
C14: ПМ 5-6 | D14: ПАРКОМЯСТО | E14: 15.12 | F14: 0.03862 | G14: 26.7 | H14: =E14+G14 -> 41.82
C15: ПМ 7-8 | D15: ПАРКОМЯСТО | E15: 15.12 | F15: 0.03862 | G15: 26.7 | H15: =E15+G15 -> 41.82
C16: ПМ 9-10 | D16: ПАРКОМЯСТО | E16: 15.12 | F16: 0.03862 | G16: 26.7 | H16: =E16+G16 -> 41.82
C17: ПМ 11-12 | D17: ПАРКОМЯСТО | E17: 15.12 | F17: 0.03862 | G17: 26.7 | H17: =E17+G17 -> 41.82
C18: ПМ 13-14 | D18: ПАРКОМЯСТО | E18: 15.12 | F18: 0.03862 | G18: 26.7 | H18: =E18+G18 -> 41.82
C19: ПМ 15-16 | D19: ПАРКОМЯСТО | E19: 15.12 | F19: 0.03862 | G19: 26.7 | H19: =E19+G19 -> 41.82
C20: ПМ 17-18 | D20: ПАРКОМЯСТО | E20: 15.12 | F20: 0.03862 | G20: 26.7 | H20: =E20+G20 -> 41.82
C21: ПМ 19-20 | D21: ПАРКОМЯСТО | E21: 15.12 | F21: 0.03862 | G21: 26.7 | H21: =E21+G21 -> 41.82
C22: ПМ 21-22 | D22: ПАРКОМЯСТО | E22: 15.12 | F22: 0.03862 | G22: 26.7 | H22: =E22+G22 -> 41.82
C23: ПМ 23-24 | D23: ПАРКОМЯСТО | E23: 15.12 | F23: 0.03862 | G23: 26.7 | H23: =E23+G23 -> 41.82
C24: ПМ 25-26 | D24: ПАРКОМЯСТО | E24: 15.12 | F24: 0.03862 | G24: 26.7 | H24: =E24+G24 -> 41.82
... C38: ПМ 47-48 | D38: ПАРКОМЯСТО | E38: 15.12 | F38: 0.03862 | G38: 26.7 | H38: =E38+G38 -> 41.82
A39: ОБЩО ПАРКОМЕСТА ЗА СУТЕРЕН "А-Б" | E39: =SUM(E12:E38) -> 391.47 | F39: =SUM(F12:F38) -> 0.99994 | G39: =SUM(G12:G38) -> 691.28 | H39: =E39+G39 -> 1082.75
A40: ПОДОБЕКТ: СГРАДА ВХОД "В" И ВХОД "Г"/ПОДОБЕКТ: II ВХОД - В И ВХОД Г/
A41: СУТЕРЕН | B41: -3.3 | C41: ПМ 1-2 | D41: ПАРКОМЯСТО | E41: 15.12 | F41: 0.05141 | G41: 26.7 | H41: =E41+G41 -> 41.82
C42: ПМ 3-4 | D42: ПАРКОМЯСТО | E42: 15.12 | F42: 0.05141 | G42: 26.7 | H42: =E42+G42 -> 41.82
C43: ПМ 5-6 | D43: ПАРКОМЯСТО | E43: 15.12 | F43: 0.05141 | G43: 26.7 | H43: =E43+G43 -> 41.82
C44: ПМ 7-8 | D44: ПАРКОМЯСТО | E44: 15.12 | F44: 0.05141 | G44: 26.7 | H44: =E44+G44 -> 41.82
C45: ПМ 9-10 | D45: ПАРКОМЯСТО | E45: 15.12 | F45: 0.05141 | G45: 26.7 | H45: =E45+G45 -> 41.82
C46: ПМ 11 | D46: ПАРКОМЯСТО | E46: 15.12 | F46: 0.05141 | G46: 26.7 | H46: =E46+G46 -> 41.82
C47: ПМ 12 | D47: ПАРКОМЯСТО | E47: 15.12 | F47: 0.05141 | G47: 26.7 | H47: =E47+G47 -> 41.82
C48: ПМ 13 | D48: ПАРКОМЯСТО | E48: 12.71 | F48: 0.04321 | G48: 22.42 | H48: =E48+G48 -> 35.13
C49: ПМ 14 | D49: ПАРКОМЯСТО | E49: 11.67 | F49: 0.03968 | G49: 20.61 | H49: =E49+G49 -> 32.28
C50: ПМ 15 | D50: ПАРКОМЯСТО | E50: 12.71 | F50: 0.04321 | G50: 22.42 | H50: =E50+G50 -> 35.13
C51: ПМ 16 | D51: ПАРКОМЯСТО | E51: 15.12 | F51: 0.05141 | G51: 26.7 | H51: =E51+G51 -> 41.82
C52: ПМ 17-18 | D52: ПАРКОМЯСТО | E52: 15.12 | F52: 0.05141 | G52: 26.7 | H52: =E52+G52 -> 41.82
C53: ПМ 19-20 | D53: ПАРКОМЯСТО | E53: 15.12 | F53: 0.05141 | G53: 26.7 | H53: =E53+G53 -> 41.82
...

Sheet Стопанка Финална
A1: Обща площ на подземието | B1: ='Жилищна част'!E336 -> 2969.22
A2: Обща плож жилищна част | B2: ='Жилищна част'!E335 -> 17326.337
A3: Общо сграда | B3: =B2+B1 -> 20295.557
A4: Процент на подземието | B4: =B1/B3 -> 0.14629902
A6: Разходи | D6: Подземие | E6: Подземие Е/% | F6: Жилищна част | G6: Жилищна част Е/%
A7: Ток | B7: 740 | D7: =$B$4*B7 -> 108.26127 | E7: =D7/3/100 -> 0.36087091 | F7: =B7-D7 -> 631.73873 | G7: =F7/100 -> 6.3173873
A8: Техническа поддръжка | B8: 700 | D8: =$B$4*B8 -> 102.40931 | E8: =D8/3/100 -> 0.34136437 | F8: =B8-D8 -> 597.59069 | G8: =F8/100 -> 5.9759069
A9: Фонд ремонти | B9: =0.12*B3 -> 2435.4668 | D9: =$B$4*B9 -> 356.3064 | E9: =D9/3/100 -> 1.187688 | F9: =B9-D9 -> 2079.1604 | G9: =F9/100 -> 20.791604
A14: Паркомясто 23-24 | B14: 5.141
A15: Стопанка | B15: 2.5
A16: Почистване | B16: =B14*1.23 -> 6.32343
A17: Ток | B17: =B14*E7 -> 1.8552373
A18: Фонд ремонти | B18: =41.8*0.12 -> 5.016 | C18: =41.8*0.12 -> 5.016
A19: Тех. поддръжка | B19: =B14*E8 -> 1.7549542
B21: =SUM(B15:B19) -> 17.449622 | C21: =B21/41.8 -> 0.41745506
A23: Апартамент Г402 | B23: 0.745
A24: Стопанка | B24: 5
A25: Асансьор | B25: =7.83*B23 -> 5.83335
A26: Почистване | B26: =33.3*B23 -> 24.8085
A27: Зелени | B27: =11.4*B23 -> 8.493
A28: Тех поддръжка | B28: =B23*G8 -> 4.4520506
A29: Вода | B29: =0.45*B23 -> 0.33525
A30: Ток | B30: =B23*G7 -> 4.7064535
A31: Фонд ремонти | B31: =B23*G9 -> 15.489745
B33: =SUM(B22:B31) -> 69.863349
A36: Паркомясто 31,32-33 | B36: 7.073
A37: Стопанка | B37: =2.5*2 -> 5 | F37: =B37 -> 5
A38: Почистване | B38: =B36*1.23 -> 8.69979 | F38: =B36*1.23 -> 8.69979
A39: Ток | B39: =B36*E7 -> 2.5524399 | F39: =B36*1.13 -> 7.99249
A40: Фонд ремонти | B40: =B36*E9 -> 8.4005172 | F40: =1.56*B36 -> 11.03388
A41: Тех. поддръжка | B41: =B36*E8 -> 2.4144702 | F41: =1.17*B36 -> 8.27541
B43: =SUM(B37:B41) -> 27.067217 | C43: =B43/75.89 -> 0.35666382 | F43: =SUM(F37:F41) -> 41.00157
A45: Апартамент Д303 | B45: 0.49
A46: Стопанка | B46: 5 | F46: 5
A47: Асансьор | B47: =7.83*B45 -> 3.8367 | F47: =B45*7.83 -> 3.8367
A48: Почистване | B48: =33.3*B45 -> 16.317 | F48: =33.3*B45 -> 16.317
A49: Зелени | B49: =11.4*B45 -> 5.586 | F49: =11.4*B45 -> 5.586
A50: Тех поддръжка | B50: =B45*G8 -> 2.9281944 | F50: =3.5*B45 -> 1.715
A51: Вода | B51: =0.45*B45 -> 0.2205 | F51: =0.45*B45 -> 0.2205
A52: Ток | B52: =B45*G7 -> 3.0955198 | F52: =4*B45 -> 1.96
...
